<?xml version="1.0" encoding="UTF-8"?>
<!-- Generated by org.testng.reporters.JUnitReportReporter -->
<testsuite hostname="DESKTOP-282TSLQ" name="testScripts.Cancellation_CompleteTesting" tests="10" failures="1" timestamp="2 Aug 2021 11:11:46 GMT" time="1874.835" errors="6">
  <testcase name="INB_Cancellation_AfterBinnerAssignment" time="623.158" classname="testScripts.Cancellation_CompleteTesting"/>
  <testcase name="OUT_Cancellation_DuringPartialconsolidation" time="0.000" classname="testScripts.Cancellation_CompleteTesting">
    <error type="java.lang.Throwable" message="Method Cancellation_CompleteTesting.OUT_Cancellation_DuringPartialconsolidation()[pri:0, instance:testScripts.Cancellation_CompleteTesting@20e2cbe0] depends on not successfully finished methods">
      <![CDATA[java.lang.Throwable: Method Cancellation_CompleteTesting.OUT_Cancellation_DuringPartialconsolidation()[pri:0, instance:testScripts.Cancellation_CompleteTesting@20e2cbe0] depends on not successfully finished methods
	at org.testng.internal.Invoker.invokeTestMethods(Invoker.java:1039)
	at org.testng.internal.TestMethodWorker.invokeTestMethods(TestMethodWorker.java:129)
	at org.testng.internal.TestMethodWorker.run(TestMethodWorker.java:112)
	at org.testng.TestRunner.privateRun(TestRunner.java:782)
	at org.testng.TestRunner.run(TestRunner.java:632)
	at org.testng.SuiteRunner.runTest(SuiteRunner.java:366)
	at org.testng.SuiteRunner.runSequentially(SuiteRunner.java:361)
	at org.testng.SuiteRunner.privateRun(SuiteRunner.java:319)
	at org.testng.SuiteRunner.run(SuiteRunner.java:268)
	at org.testng.SuiteRunnerWorker.runSuite(SuiteRunnerWorker.java:52)
	at org.testng.SuiteRunnerWorker.run(SuiteRunnerWorker.java:86)
	at org.testng.TestNG.runSuitesSequentially(TestNG.java:1244)
	at org.testng.TestNG.runSuitesLocally(TestNG.java:1169)
	at org.testng.TestNG.run(TestNG.java:1064)
	at org.testng.remote.RemoteTestNG.run(RemoteTestNG.java:113)
	at org.testng.remote.RemoteTestNG.initAndRun(RemoteTestNG.java:206)
	at org.testng.remote.RemoteTestNG.main(RemoteTestNG.java:177)
]]>
    </error>
  </testcase> <!-- OUT_Cancellation_DuringPartialconsolidation -->
  <testcase name="OUT_Cancellation_DuringPartialpicking" time="0.000" classname="testScripts.Cancellation_CompleteTesting">
    <error type="java.lang.Throwable" message="Method Cancellation_CompleteTesting.OUT_Cancellation_DuringPartialpicking()[pri:0, instance:testScripts.Cancellation_CompleteTesting@20e2cbe0] depends on not successfully finished methods">
      <![CDATA[java.lang.Throwable: Method Cancellation_CompleteTesting.OUT_Cancellation_DuringPartialpicking()[pri:0, instance:testScripts.Cancellation_CompleteTesting@20e2cbe0] depends on not successfully finished methods
	at org.testng.internal.Invoker.invokeTestMethods(Invoker.java:1039)
	at org.testng.internal.TestMethodWorker.invokeTestMethods(TestMethodWorker.java:129)
	at org.testng.internal.TestMethodWorker.run(TestMethodWorker.java:112)
	at org.testng.TestRunner.privateRun(TestRunner.java:782)
	at org.testng.TestRunner.run(TestRunner.java:632)
	at org.testng.SuiteRunner.runTest(SuiteRunner.java:366)
	at org.testng.SuiteRunner.runSequentially(SuiteRunner.java:361)
	at org.testng.SuiteRunner.privateRun(SuiteRunner.java:319)
	at org.testng.SuiteRunner.run(SuiteRunner.java:268)
	at org.testng.SuiteRunnerWorker.runSuite(SuiteRunnerWorker.java:52)
	at org.testng.SuiteRunnerWorker.run(SuiteRunnerWorker.java:86)
	at org.testng.TestNG.runSuitesSequentially(TestNG.java:1244)
	at org.testng.TestNG.runSuitesLocally(TestNG.java:1169)
	at org.testng.TestNG.run(TestNG.java:1064)
	at org.testng.remote.RemoteTestNG.run(RemoteTestNG.java:113)
	at org.testng.remote.RemoteTestNG.initAndRun(RemoteTestNG.java:206)
	at org.testng.remote.RemoteTestNG.main(RemoteTestNG.java:177)
]]>
    </error>
  </testcase> <!-- OUT_Cancellation_DuringPartialpicking -->
  <testcase name="OUT_Cancellation_DuringPartialDispatch" time="0.000" classname="testScripts.Cancellation_CompleteTesting">
    <error type="java.lang.Throwable" message="Method Cancellation_CompleteTesting.OUT_Cancellation_DuringPartialDispatch()[pri:0, instance:testScripts.Cancellation_CompleteTesting@20e2cbe0] depends on not successfully finished methods">
      <![CDATA[java.lang.Throwable: Method Cancellation_CompleteTesting.OUT_Cancellation_DuringPartialDispatch()[pri:0, instance:testScripts.Cancellation_CompleteTesting@20e2cbe0] depends on not successfully finished methods
	at org.testng.internal.Invoker.invokeTestMethods(Invoker.java:1039)
	at org.testng.internal.TestMethodWorker.invokeTestMethods(TestMethodWorker.java:129)
	at org.testng.internal.TestMethodWorker.run(TestMethodWorker.java:112)
	at org.testng.TestRunner.privateRun(TestRunner.java:782)
	at org.testng.TestRunner.run(TestRunner.java:632)
	at org.testng.SuiteRunner.runTest(SuiteRunner.java:366)
	at org.testng.SuiteRunner.runSequentially(SuiteRunner.java:361)
	at org.testng.SuiteRunner.privateRun(SuiteRunner.java:319)
	at org.testng.SuiteRunner.run(SuiteRunner.java:268)
	at org.testng.SuiteRunnerWorker.runSuite(SuiteRunnerWorker.java:52)
	at org.testng.SuiteRunnerWorker.run(SuiteRunnerWorker.java:86)
	at org.testng.TestNG.runSuitesSequentially(TestNG.java:1244)
	at org.testng.TestNG.runSuitesLocally(TestNG.java:1169)
	at org.testng.TestNG.run(TestNG.java:1064)
	at org.testng.remote.RemoteTestNG.run(RemoteTestNG.java:113)
	at org.testng.remote.RemoteTestNG.initAndRun(RemoteTestNG.java:206)
	at org.testng.remote.RemoteTestNG.main(RemoteTestNG.java:177)
]]>
    </error>
  </testcase> <!-- OUT_Cancellation_DuringPartialDispatch -->
  <testcase name="OUT_Cancellation_atOrderisinDispatchDashboard" time="0.000" classname="testScripts.Cancellation_CompleteTesting">
    <error type="java.lang.Throwable" message="Method Cancellation_CompleteTesting.OUT_Cancellation_atOrderisinDispatchDashboard()[pri:0, instance:testScripts.Cancellation_CompleteTesting@20e2cbe0] depends on not successfully finished methods">
      <![CDATA[java.lang.Throwable: Method Cancellation_CompleteTesting.OUT_Cancellation_atOrderisinDispatchDashboard()[pri:0, instance:testScripts.Cancellation_CompleteTesting@20e2cbe0] depends on not successfully finished methods
	at org.testng.internal.Invoker.invokeTestMethods(Invoker.java:1039)
	at org.testng.internal.TestMethodWorker.invokeTestMethods(TestMethodWorker.java:129)
	at org.testng.internal.TestMethodWorker.run(TestMethodWorker.java:112)
	at org.testng.TestRunner.privateRun(TestRunner.java:782)
	at org.testng.TestRunner.run(TestRunner.java:632)
	at org.testng.SuiteRunner.runTest(SuiteRunner.java:366)
	at org.testng.SuiteRunner.runSequentially(SuiteRunner.java:361)
	at org.testng.SuiteRunner.privateRun(SuiteRunner.java:319)
	at org.testng.SuiteRunner.run(SuiteRunner.java:268)
	at org.testng.SuiteRunnerWorker.runSuite(SuiteRunnerWorker.java:52)
	at org.testng.SuiteRunnerWorker.run(SuiteRunnerWorker.java:86)
	at org.testng.TestNG.runSuitesSequentially(TestNG.java:1244)
	at org.testng.TestNG.runSuitesLocally(TestNG.java:1169)
	at org.testng.TestNG.run(TestNG.java:1064)
	at org.testng.remote.RemoteTestNG.run(RemoteTestNG.java:113)
	at org.testng.remote.RemoteTestNG.initAndRun(RemoteTestNG.java:206)
	at org.testng.remote.RemoteTestNG.main(RemoteTestNG.java:177)
]]>
    </error>
  </testcase> <!-- OUT_Cancellation_atOrderisinDispatchDashboard -->
  <testcase name="INB_Cancellation_DuringBinning" time="689.636" classname="testScripts.Cancellation_CompleteTesting"/>
  <testcase name="OUT_Cancellation_pickgenerationScreen" time="106.187" classname="testScripts.Cancellation_CompleteTesting">
    <failure type="java.lang.AssertionError" message="expected [true] but found [false]">
      <![CDATA[java.lang.AssertionError: expected [true] but found [false]
	at org.testng.Assert.fail(Assert.java:94)
	at org.testng.Assert.failNotEquals(Assert.java:513)
	at org.testng.Assert.assertTrue(Assert.java:42)
	at org.testng.Assert.assertTrue(Assert.java:52)
	at testScripts.CommonFunctions.verify(CommonFunctions.java:156)
	at testScripts.Cancellation_CompleteTesting.OUT_Cancellation_pickgenerationScreen(Cancellation_CompleteTesting.java:990)
	at sun.reflect.NativeMethodAccessorImpl.invoke0(Native Method)
	at sun.reflect.NativeMethodAccessorImpl.invoke(NativeMethodAccessorImpl.java:62)
	at sun.reflect.DelegatingMethodAccessorImpl.invoke(DelegatingMethodAccessorImpl.java:43)
	at java.lang.reflect.Method.invoke(Method.java:498)
	at org.testng.internal.MethodInvocationHelper.invokeMethod(MethodInvocationHelper.java:86)
	at org.testng.internal.Invoker.invokeMethod(Invoker.java:645)
	at org.testng.internal.Invoker.invokeTestMethod(Invoker.java:822)
	at org.testng.internal.Invoker.invokeTestMethods(Invoker.java:1130)
	at org.testng.internal.TestMethodWorker.invokeTestMethods(TestMethodWorker.java:129)
	at org.testng.internal.TestMethodWorker.run(TestMethodWorker.java:112)
	at org.testng.TestRunner.privateRun(TestRunner.java:782)
	at org.testng.TestRunner.run(TestRunner.java:632)
	at org.testng.SuiteRunner.runTest(SuiteRunner.java:366)
	at org.testng.SuiteRunner.runSequentially(SuiteRunner.java:361)
	at org.testng.SuiteRunner.privateRun(SuiteRunner.java:319)
	at org.testng.SuiteRunner.run(SuiteRunner.java:268)
	at org.testng.SuiteRunnerWorker.runSuite(SuiteRunnerWorker.java:52)
	at org.testng.SuiteRunnerWorker.run(SuiteRunnerWorker.java:86)
	at org.testng.TestNG.runSuitesSequentially(TestNG.java:1244)
	at org.testng.TestNG.runSuitesLocally(TestNG.java:1169)
	at org.testng.TestNG.run(TestNG.java:1064)
	at org.testng.remote.RemoteTestNG.run(RemoteTestNG.java:113)
	at org.testng.remote.RemoteTestNG.initAndRun(RemoteTestNG.java:206)
	at org.testng.remote.RemoteTestNG.main(RemoteTestNG.java:177)
]]>
    </failure>
  </testcase> <!-- OUT_Cancellation_pickgenerationScreen -->
  <testcase name="OUT_Cancellation_atOrderisinConsolidationDashboard" time="0.000" classname="testScripts.Cancellation_CompleteTesting">
    <error type="java.lang.Throwable" message="Method Cancellation_CompleteTesting.OUT_Cancellation_atOrderisinConsolidationDashboard()[pri:0, instance:testScripts.Cancellation_CompleteTesting@20e2cbe0] depends on not successfully finished methods">
      <![CDATA[java.lang.Throwable: Method Cancellation_CompleteTesting.OUT_Cancellation_atOrderisinConsolidationDashboard()[pri:0, instance:testScripts.Cancellation_CompleteTesting@20e2cbe0] depends on not successfully finished methods
	at org.testng.internal.Invoker.invokeTestMethods(Invoker.java:1039)
	at org.testng.internal.TestMethodWorker.invokeTestMethods(TestMethodWorker.java:129)
	at org.testng.internal.TestMethodWorker.run(TestMethodWorker.java:112)
	at org.testng.TestRunner.privateRun(TestRunner.java:782)
	at org.testng.TestRunner.run(TestRunner.java:632)
	at org.testng.SuiteRunner.runTest(SuiteRunner.java:366)
	at org.testng.SuiteRunner.runSequentially(SuiteRunner.java:361)
	at org.testng.SuiteRunner.privateRun(SuiteRunner.java:319)
	at org.testng.SuiteRunner.run(SuiteRunner.java:268)
	at org.testng.SuiteRunnerWorker.runSuite(SuiteRunnerWorker.java:52)
	at org.testng.SuiteRunnerWorker.run(SuiteRunnerWorker.java:86)
	at org.testng.TestNG.runSuitesSequentially(TestNG.java:1244)
	at org.testng.TestNG.runSuitesLocally(TestNG.java:1169)
	at org.testng.TestNG.run(TestNG.java:1064)
	at org.testng.remote.RemoteTestNG.run(RemoteTestNG.java:113)
	at org.testng.remote.RemoteTestNG.initAndRun(RemoteTestNG.java:206)
	at org.testng.remote.RemoteTestNG.main(RemoteTestNG.java:177)
]]>
    </error>
  </testcase> <!-- OUT_Cancellation_atOrderisinConsolidationDashboard -->
  <testcase name="INB_Cancellation_DockinScreen" time="455.854" classname="testScripts.Cancellation_CompleteTesting"/>
  <testcase name="OUT_Cancellation_Orderisin_PickerDashboardScreen" time="0.000" classname="testScripts.Cancellation_CompleteTesting">
    <error type="java.lang.Throwable" message="Method Cancellation_CompleteTesting.OUT_Cancellation_Orderisin_PickerDashboardScreen()[pri:0, instance:testScripts.Cancellation_CompleteTesting@20e2cbe0] depends on not successfully finished methods">
      <![CDATA[java.lang.Throwable: Method Cancellation_CompleteTesting.OUT_Cancellation_Orderisin_PickerDashboardScreen()[pri:0, instance:testScripts.Cancellation_CompleteTesting@20e2cbe0] depends on not successfully finished methods
	at org.testng.internal.Invoker.invokeTestMethods(Invoker.java:1039)
	at org.testng.internal.TestMethodWorker.invokeTestMethods(TestMethodWorker.java:129)
	at org.testng.internal.TestMethodWorker.run(TestMethodWorker.java:112)
	at org.testng.TestRunner.privateRun(TestRunner.java:782)
	at org.testng.TestRunner.run(TestRunner.java:632)
	at org.testng.SuiteRunner.runTest(SuiteRunner.java:366)
	at org.testng.SuiteRunner.runSequentially(SuiteRunner.java:361)
	at org.testng.SuiteRunner.privateRun(SuiteRunner.java:319)
	at org.testng.SuiteRunner.run(SuiteRunner.java:268)
	at org.testng.SuiteRunnerWorker.runSuite(SuiteRunnerWorker.java:52)
	at org.testng.SuiteRunnerWorker.run(SuiteRunnerWorker.java:86)
	at org.testng.TestNG.runSuitesSequentially(TestNG.java:1244)
	at org.testng.TestNG.runSuitesLocally(TestNG.java:1169)
	at org.testng.TestNG.run(TestNG.java:1064)
	at org.testng.remote.RemoteTestNG.run(RemoteTestNG.java:113)
	at org.testng.remote.RemoteTestNG.initAndRun(RemoteTestNG.java:206)
	at org.testng.remote.RemoteTestNG.main(RemoteTestNG.java:177)
]]>
    </error>
  </testcase> <!-- OUT_Cancellation_Orderisin_PickerDashboardScreen -->
</testsuite> <!-- testScripts.Cancellation_CompleteTesting -->
